job started ....
LibriSpeech: 585, train_ds: 61425
GPUassert: initialization error /tmp/pip-req-build-a8243qk8/src/gpuRIR_cuda.cu 793
GPUassert: initialization error /tmp/pip-req-build-a8243qk8/src/gpuRIR_cuda.cu 793
GPUassert: initialization error /tmp/pip-req-build-a8243qk8/src/gpuRIR_cuda.cu 793
GPUassert: initialization error /tmp/pip-req-build-a8243qk8/src/gpuRIR_cuda.cu 793
Traceback (most recent call last):
  File "/u/battula12/.conda/envs/moving_source/lib/python3.9/site-packages/torch/utils/data/dataloader.py", line 1163, in _try_get_data
    data = self._data_queue.get(timeout=timeout)
  File "/u/battula12/.conda/envs/moving_source/lib/python3.9/multiprocessing/queues.py", line 113, in get
    if not self._poll(timeout):
  File "/u/battula12/.conda/envs/moving_source/lib/python3.9/multiprocessing/connection.py", line 262, in poll
    return self._poll(timeout)
  File "/u/battula12/.conda/envs/moving_source/lib/python3.9/multiprocessing/connection.py", line 429, in _poll
    r = wait([self], timeout)
  File "/u/battula12/.conda/envs/moving_source/lib/python3.9/multiprocessing/connection.py", line 936, in wait
    ready = selector.select(timeout)
  File "/u/battula12/.conda/envs/moving_source/lib/python3.9/selectors.py", line 416, in select
    fd_event_list = self._selector.poll(timeout)
  File "/u/battula12/.conda/envs/moving_source/lib/python3.9/site-packages/torch/utils/data/_utils/signal_handling.py", line 66, in handler
    _error_if_any_worker_fails()
RuntimeError: DataLoader worker (pid 1280674) exited unexpectedly with exit code 3. Details are lost due to multiprocessing. Rerunning with num_workers=0 may give better error trace.

The above exception was the direct cause of the following exception:

Traceback (most recent call last):
  File "/u/battula12/Projects/Datasets/RandomTrajectory.py", line 371, in <module>
    for _batch_idx, val in enumerate(train_loader):
  File "/u/battula12/.conda/envs/moving_source/lib/python3.9/site-packages/torch/utils/data/dataloader.py", line 681, in __next__
    data = self._next_data()
  File "/u/battula12/.conda/envs/moving_source/lib/python3.9/site-packages/torch/utils/data/dataloader.py", line 1359, in _next_data
    idx, data = self._get_data()
  File "/u/battula12/.conda/envs/moving_source/lib/python3.9/site-packages/torch/utils/data/dataloader.py", line 1325, in _get_data
    success, data = self._try_get_data()
  File "/u/battula12/.conda/envs/moving_source/lib/python3.9/site-packages/torch/utils/data/dataloader.py", line 1176, in _try_get_data
    raise RuntimeError('DataLoader worker (pid(s) {}) exited unexpectedly'.format(pids_str)) from e
RuntimeError: DataLoader worker (pid(s) 1280674, 1280675, 1280676, 1280677) exited unexpectedly
job finished!
